Workbook

Sheet Источники
A1: Показатель/цифра | B1: Значение | C1: Ед. | D1: Источник (URL/документ) | E1: Дата доступа | F1: Примечание
A2: Аренда dark kitchen в Москве (с оборудованием) | B2: 300 000 | C2: ₽/мес | D2: https://www.avito.ru/moskva/kommercheskaya_nedvizhimost/gotovyy_tseh_dark_kitchen_110_m_bez_komissii_7851962280?context=H4sIAAAAAAAA_wE_AMD_YToyOntzOjEzOiJsb2NhbFByaW9yaXR5IjtiOjA7czoxOiJ4IjtzOjE2OiJEakJUb3JHNVZ3R3FOdUV3Ijt9lcmntz8AAAA | E2: 46091
A3: Зарплата повара / производственного персонала | B3: 80000 | C3: ₽/мес | D3: https://hh.ru/vacancy/130737974?query=%D0%BF%D0%BE%D0%B2%D0%B0%D1%80-%D1%83%D0%BD%D0%B8%D0%B2%D0%B5%D1%80%D1%81%D0%B0%D0%BB&hhtmFrom=vacancy_search_list | E3: 2026-03-07 | F3: Ориентир по HH
A4: Зарплата курьера / логиста | B4: 130000 | C4: ₽/мес | D4: https://hh.ru/vacancy/129289894?query=%D0%B4%D0%BE%D1%81%D1%82%D0%B0%D0%B2%D1%89%D0%B8%D0%BA&hhtmFrom=vacancy_search_list | E4: 2026-03-07 | F4: Ориентир по HH | G4: та же ссылка, что и у повара
A5: Средняя цена подписки meal prep | B5: 42260 | C5: ₽/мес | D5: 1. https://levelkitchen.com/?srsltid=AfmBOorcKwF_4PzMKAc5iJjsk-COY8CdQSPlp-KiNijnh_-9V28WThvU. 2. https://growfood.pro/. 3. https://letbefit.ru/?srsltid=AfmBOopRRBb6kPheMIHy3qZ_9Jow9VSy4rmqlYMvVTxDXiGY0OF0x8XZ 4. https://www.justfood.pro/ | E5: 2026-03-07
A12: Объем рынка готовой еды | B12: 1.14 | C12: трлн руб. | D12: https://www.kommersant.ru/doc/8251984 https://www.sostav.ru/publication/rossijskij-rynok-gotovoj-edy-vyros-na-tret-80164.html | E12: 46088 | F12: Данные InfoLine
A13: Объем рынка готовых рационов в РФ | B13: 17 | C13: млрд руб. | D13: https://incrussia.ru/news/gotovye-ratsiony-nabirayut-populyarnost-rynok-vyros-na-13/ | E13: 2026-03-07
A14: Среднегодовой рост рынка готовых рационов в РФ | B14: 12.8 | C14: % | D14: https://incrussia.ru/news/gotovye-ratsiony-nabirayut-populyarnost-rynok-vyros-na-13/ | E14: 2026-03-07

Sheet Ввод (Inputs)
A1: Ввод (Inputs)
A3: Ключевые вводные и драйверы | B3: Значение | C3: Ед. | D3: Источник (ID/URL) | E3: Комментарий
A5: География (город / зона доставки) | B5: Москва
A6: Площадь кухни / dark kitchen | B6: 110 | C6: м² | D6: =Источники!D2 -> https://www.avito.ru/moskva/kommercheskaya_nedvizhimost/gotovyy_tseh_dark_kitchen_110_m_bez_komissii_7851962280?context=H4sIAAAAAAAA_wE_AMD_YToyOntzOjEzOiJsb2NhbFByaW9yaXR5IjtiOjA7czoxOiJ4IjtzOjE2OiJEakJUb3JHNVZ3R3FOdUV3Ijt9lcmntz8AAAA
A7: Горизонт модели | B7: 24 | C7: мес | D7: Допущение
A8: Дней доставки в месяце | B8: 30 | C8: дней | D8: Допущение
A9: Начальная загрузка % | B9: 0.05 | C9: % | D9: Допущение
A10: Начальная загрузка (клиентов) | B10: =B15*B9 -> 24.553571 | C10: шт
A11: Прирост загрузки в первые 5 месяцев % | B11: ='Анализ чувствительности'!E21 -> 0.02 | C11: % | D11: От максимальной загрузки
A12: Прирост загрузки (клиентов) в первые 5 месяцев | B12: =B15*B11 -> 9.8214286 | C12: шт
A13: Прирост загрузки после 5 месяцев % | B13: 0.05 | C13: % | D13: От максимальной загрузки
A14: Прирост загрузки (клиентов) после 5 месяцев | B14: =B15*B13 -> 24.553571 | C14: шт
A15: Максимальная загрузка (макс. кол-во подписчиков) | B15: =(110*(5000/280))/4 -> 491.07143 | C15: подписчиков | D15: https://optima-invest.ru/ekb/obekty/pishchevoe_proizvodstvo_dark_kitchen_zakrytaya_kukhnya_postavka_gotovoy_edy_v_upakovke/ | E15: 17,8 лотков на 1 м², 4 приема пищи в день на клиента
A16: Драйверы выручки и LTV
A17: Средняя цена подписки в месяц (ARPU) | B17: ='Анализ чувствительности'!A5 -> 42260 | C17: ₽/мес | D17: https://levelkitchen.com/?srsltid=AfmBOorcKwF_4PzMKAc5iJjsk-COY8CdQSPlp-KiNijnh_-9V28WThvU https://growfood.pro/ https://letbefit.ru/?srsltid=AfmBOopRRBb6kPheMIHy3qZ_9Jow9VSy4rmqlYMvVTxDXiGY0OF0x8XZ https://www.justfood.pro/ | E17: Средняя ежемесячная выручка на одного подписчика
A18: Food cost как % от выручки | B18: 0.33 | C18: % | D18: https://companies.rbc.ru/news/RELaZl5K49/zatratyi-na-produktyi-dostigli-v-srednem-33-ot-stoimosti-blyud-v-restoranah/ | E18: Продукты + упаковка
A19: Доставка и упаковка как % от выручки | B19: 0.2 | C19: % | D19: https://www.retail.ru/rbc/pressreleases/dolya-dostavki-v-strukture-rynka-edy-mozhet-vyrasti-do-30-k-2030-godu/ https://smartomato.ru/blog/unit-economics-food-delivery/#:~:text=%D0%90%20%D0%B2%D1%81%D0%B5%2C%20%D1%87%D1%82%D0%BE%20%D1%81%D1%8D%D0%BA%D0%BE%D0%BD%D0%BE%D0%BC%D0%B8%D0%BB%D0%B8%2C%20%D0%BE%D1%82%D0%B4%D0%B0%D0%B9%D1%82%D0%B5%20%D0%B2%20%D0%BC%D0%B0%D1%80%D0%BA%D0%B5%D1%82%D0%B8%D0%BD%D0%B3.
A20: Платёжные и прочие переменные комиссии | B20: 0.01 | C20: % | D20: https://tochka.com/acquiring/?utm_campaign=g_acquiring_ | E20: Эквайринг, экосистема и тд.
A21: Маркетинг / привлечение в месяц | B21: ='Анализ чувствительности'!E19 -> 200000 | C21: ₽/мес | D21: https://voropaevmedia.com/reklama-dostavki-edi | E21: Рекламный бюджет
A22: Новых подписчиков в месяц | B22: 10 | C22: клиентов/мес
A23: Количество оплат в месяц на одного клиента | B23: 1 | C23: оплата/мес | D23: Допущение | E23: Для подписки обычно 1
A24: Lifetime клиента | B24: 5 | C24: мес | D24: https://www.bottle.com/blog/key-financial-operational-benchmarks-for-meal-prep-businesses | E24: Средний срок жизни подписчика
A25: OPEX
A26: Ставка аренды | B26: =Источники!B2 -> 300 000 | C26: ₽/мес | D26: =Источники!D2 -> https://www.avito.ru/moskva/kommercheskaya_nedvizhimost/gotovyy_tseh_dark_kitchen_110_m_bez_komissii_7851962280?context=H4sIAAAAAAAA_wE_AMD_YToyOntzOjEzOiJsb2NhbFByaW9yaXR5IjtiOjA7czoxOiJ4IjtzOjE2OiJEakJUb3JHNVZ3R3FOdUV3Ijt9lcmntz8AAAA
A27: Коммунальные | B27: 30000 | C27: ₽/мес | D27: https://www.biztotal.ru/publikacii/kakiye_osnovnyye_raskhody_v_restorane_32030.html
A28: Интернет / IT / CRM | B28: 4000 | C28: ₽/мес | D28: https://restik.com/automation/restoran/ https://moskva.beeline.ru/business/office-internet/wi-fi/
A29: Вывоз мусора | B29: =549*15 -> 8235 | C29: ₽/мес | D29: https://eko-polis.ru/stoimost-vyvoza-musora/ | E29: Раз в 2 дня
A30: Прочие OPEX | B30: 20000 | C30: ₽/мес
A31: ФОТ
A32: Количество поваров (ставок) | B32: 3 | C32: чел
A33: ЗП повара (на 1 ставку) | B33: 80000 | C33: ₽/мес | D33: https://hh.ru/vacancy/130737974?query=%D0%BF%D0%BE%D0%B2%D0%B0%D1%80-%D1%83%D0%BD%D0%B8%D0%B2%D0%B5%D1%80%D1%81%D0%B0%D0%BB&hhtmFrom=vacancy_search_list
A34: Количество курьеров | B34: 4 | C34: чел
A35: ЗП администратора по доставке | B35: 80000 | C35: ₽/мес | D35: https://hh.ru/vacancy/130896280?query=%D0%BC%D0%B5%D0%BD%D0%B5%D0%B4%D0%B6%D0%B5%D1%80+%D0%BA%D1%83%D1%80%D1%8C%D0%B5%D1%80%D1%81%D0%BA%D0%BE%D0%B9+%D1%81%D0%BB%D1%83%D0%B6%D0%B1%D1%8B&hhtmFrom=vacancy_search_list
A36: ЗП курьера (на 1 ставку) | B36: 130000 | C36: ₽/мес | D36: https://hh.ru/vacancy/129289894?query=%D0%B4%D0%BE%D1%81%D1%82%D0%B0%D0%B2%D1%89%D0%B8%D0%BA&hhtmFrom=vacancy_search_list
A37: Взносы на ФОТ | B37: =((B33*B32)+(B36*B34))*30% -> 228000 | C37: ₽ | E37: В общем 30% от ФОТ
A38: Налоги и финпараметры
A39: Налог как % от прибыли до налога | B39: 0.25 | C39: %
A40: Ставка дисконтирования (годовая) | B40: 0.2 | C40: %
A41: Срок амортизации CAPEX | B41: 120 | C41: мес
A42: CAPEX (разовые затраты)
...

Sheet Unit Economics
A1: Юнит-экономика (Unit Economics)
A4: МАРЖИНАЛЬНОСТЬ ОДНОГО ПОДПИСЧИКА / МЕС | B4: Значение
A5: Средний доход с подписчика в месяц (Revenue) | B5: ='Ввод (Inputs)'!B17*'Ввод (Inputs)'!B23 -> 42260
A6: Переменные расходы на подписчика в месяц (Variable Cost) | B6: ='Ввод (Inputs)'!B17*('Ввод (Inputs)'!B18+'Ввод (Inputs)'!B19+'Ввод (Inputs)'!B20) -> 22820.4
A7: Маржа на подписчика в месяц (Contribution Margin) | B7: =B5-B6 -> 19439.6
A8: Маржинальность (%) | B8: =B7/B5 -> 0.46
A10: ПОСТОЯННЫЕ РАСХОДЫ (Fixed Costs) | B10: Значение
A11: Аренда кухни | B11: ='Ввод (Inputs)'!B26 -> 300 000
A12: ФОТ | B12: ='Ввод (Inputs)'!B32*'Ввод (Inputs)'!B33+'Ввод (Inputs)'!B34*'Ввод (Inputs)'!B36+'Ввод (Inputs)'!B35+'Ввод (Inputs)'!B37 -> 1068000
A13: Маркетинг + коммунальные + прочие | B13: ='Ввод (Inputs)'!B21+'Ввод (Inputs)'!B27+'Ввод (Inputs)'!B28+'Ввод (Inputs)'!B29+'Ввод (Inputs)'!B30 -> 262235
A14: ИТОГО постоянных расходов/мес | B14: =SUM(B11:B13) -> 1330235
A16: ТОЧКА БЕЗУБЫТОЧНОСТИ (Break-Even) | B16: Значение
A17: Break-even (подписчиков/мес) | B17: =B14/B7 -> 68.429134
A18: Break-even как % от целевой мощности | B18: =B17/'Ввод (Inputs)'!B15 -> 0.1393466
A20: ЗАПАС ПРОЧНОСТИ (Margin of Safety) | B20: Значение
A21: Активные подписчики в мес. 1 | B21: ='Ввод (Inputs)'!B15*'Ввод (Inputs)'!B9 -> 24.553571
A22: Запас прочности (подписчиков) | B22: =B21-B17 -> -43.875563
A23: Запас прочности (%) | B23: =B22/B21 -> -1.786932
A25: РАСЧЁТ ЦЕЛЕВОЙ ПРИБЫЛИ | B25: Значение
A26: Целевая чистая прибыль/мес | B26: 500000
A27: Нужно активных подписчиков/мес для целевой прибыли | B27: =(B26+B14)/B7 -> 94.149828
A29: РАСЧЁТ LTV | B29: Значение
A30: Оплат на 1 клиента в месяц | B30: ='Ввод (Inputs)'!B23 -> 1
A31: Срок жизни клиента (LifeTime, мес) | B31: ='Ввод (Inputs)'!B24 -> 5
A32: LTV | B32: =B30*B31*B7 -> 97198
A33: РАСЧЁТ CAC (первые 5 месяцев) | B33: Значение
A34: Количество привлечённых клиентов / мес | B34: ='Ввод (Inputs)'!B15*'Ввод (Inputs)'!B11 -> 9.8214286
A35: CAC | B35: ='Ввод (Inputs)'!B21/B34 -> 20363.636
A36: РАСЧЁТ LTV/CAC (первые 5 месяцев) | B36: Значение
A37: LTV/CAC | B37: =B32/B35 -> 4.7731161
A38: РАСЧЁТ CAC (после 5 месяцев) | B38: Значение
A39: Количество привлечённых клиентов / мес | B39: ='Ввод (Inputs)'!B15*'Ввод (Inputs)'!B13 -> 24.553571
A40: CAC | B40: ='Ввод (Inputs)'!B21/B39 -> 8145.4545
A41: РАСЧЁТ LTV/CAC (первые 5 месяцев) | B41: Значение
A42: LTV/CAC | B42: =B32/B40 -> 11.93279

Sheet Рынок_TAM_SAM_SOM
A1: TAM / SAM / SOM
A3: Вводные
A4: Показатель | B4: Значение | C4: Ед. | D4: Источник (ID)
A6: Объем рынка готовой еды | B6: =Источники!B12 -> 1.14 | C6: =Источники!C12 -> трлн руб. | D6: S11
A7: Объем рынка готовых рационов в РФ | B7: =Источники!B13 -> 17 | C7: =Источники!C13 -> млрд руб. | D7: S12
A8: Доля Москвы на рынке готовых рационов | B8: 0.45 | D8: См. отчет в Word
A9: Средняя цена подписки в месяц | B9: =Источники!B5 -> 42260 | C9: руб./мес | D9: S4,S5
A10: Достижимая доля рынка | B10: 0.026 | D10: См. отчет в Word
A15: Расчёты
A16: TAM (год) | B16: =B6 -> 1.14 | C16: =C6 -> трлн руб.
A17: SAM (год) — доступная часть | B17: =B7*B8 -> 7.65 | C17: =C7 -> млрд руб.
A18: SOM (год) — достижимая часть | B18: =B17*B10*1000 -> 198.9 | C18: млн руб.

Sheet P&L_24м
A1: P&L (ОПиУ) — 24 месяца (динамически от Inputs + сценариев)
A3: Статья | B3: М0 | C3: М1 | D3: М2 | E3: М3 | F3: М4 | G3: М5 | H3: М6 | I3: М7 | J3: М8 | K3: М9 | L3: М10 | M3: М11 | N3: М12 | O3: М13 | P3: М14 | Q3: М15 | R3: М16 | S3: М17 | T3: М18 | U3: М19 | V3: М20 | W3: М21 | X3: М22 | Y3: М23 | Z3: М24
A4: Загрузка | B4: 0 | C4: ='Ввод (Inputs)'!B9 -> 0.05 | D4: =C4+'Ввод (Inputs)'!$B$11 -> 0.07 | E4: =D4+'Ввод (Inputs)'!$B$11 -> 0.09 | F4: =E4+'Ввод (Inputs)'!$B$11 -> 0.11 | G4: =F4+'Ввод (Inputs)'!$B$11 -> 0.13 | H4: =G4+'Ввод (Inputs)'!B13-'Ввод (Inputs)'!B9 -> 0.13 | I4: =H4+'Ввод (Inputs)'!$B$13-'Ввод (Inputs)'!$B$11 -> 0.16 | J4: =I4+'Ввод (Inputs)'!$B$13-'Ввод (Inputs)'!$B$11 -> 0.19 | K4: =J4+'Ввод (Inputs)'!$B$13-'Ввод (Inputs)'!$B$11 -> 0.22 | L4: =K4+'Ввод (Inputs)'!$B$13-'Ввод (Inputs)'!$B$11 -> 0.25 | M4: =L4+'Ввод (Inputs)'!$B$13-'Ввод (Inputs)'!$B$11 -> 0.28 | N4: =M4+'Ввод (Inputs)'!$B$13-'Ввод (Inputs)'!$B$11 -> 0.31 | O4: =N4+'Ввод (Inputs)'!$B$13-'Ввод (Inputs)'!$B$11 -> 0.34 | P4: =O4+'Ввод (Inputs)'!$B$13-'Ввод (Inputs)'!$B$11 -> 0.37 | ... Z4: =Y4+'Ввод (Inputs)'!$B$13-'Ввод (Inputs)'!$B$11 -> 0.67
A5: Количество заказов | B5: 0 | C5: ='Ввод (Inputs)'!B10 -> 24.553571 | D5: =C5+'Ввод (Inputs)'!$B$12 -> 34.375 | E5: =D5+'Ввод (Inputs)'!$B$12 -> 44.196429 | F5: =E5+'Ввод (Inputs)'!$B$12 -> 54.017857 | G5: =F5+'Ввод (Inputs)'!$B$12 -> 63.839286 | H5: =G5+'Ввод (Inputs)'!B14-'Ввод (Inputs)'!B10 -> 63.839286 | I5: =H5+'Ввод (Inputs)'!$B$14-'Ввод (Inputs)'!$B$12 -> 78.571429 | J5: =I5+'Ввод (Inputs)'!$B$14-'Ввод (Inputs)'!$B$12 -> 93.303571 | K5: =J5+'Ввод (Inputs)'!$B$14-'Ввод (Inputs)'!$B$12 -> 108.03571 | L5: =K5+'Ввод (Inputs)'!$B$14-'Ввод (Inputs)'!$B$12 -> 122.76786 | M5: =L5+'Ввод (Inputs)'!$B$14-'Ввод (Inputs)'!$B$12 -> 137.5 | N5: =M5+'Ввод (Inputs)'!$B$14-'Ввод (Inputs)'!$B$12 -> 152.23214 | O5: =N5+'Ввод (Inputs)'!$B$14-'Ввод (Inputs)'!$B$12 -> 166.96429 | P5: =O5+'Ввод (Inputs)'!$B$14-'Ввод (Inputs)'!$B$12 -> 181.69643 | ... Z5: =Y5+'Ввод (Inputs)'!$B$14-'Ввод (Inputs)'!$B$12 -> 329.01786
A6: Выручка | B6: 0 | C6: =C5*'Ввод (Inputs)'!$B$17 -> 1037633.9 | D6: =D5*'Ввод (Inputs)'!B17 -> 1452687.5 | E6: =E5*'Ввод (Inputs)'!$B$17 -> 1867741.1 | F6: =F5*'Ввод (Inputs)'!$B$17 -> 2282794.6 | G6: =G5*'Ввод (Inputs)'!$B$17 -> 2697848.2 | H6: =H5*'Ввод (Inputs)'!$B$17 -> 2697848.2 | I6: =I5*'Ввод (Inputs)'!$B$17 -> 3320428.6 | J6: =J5*'Ввод (Inputs)'!$B$17 -> 3943008.9 | K6: =K5*'Ввод (Inputs)'!$B$17 -> 4565589.3 | L6: =L5*'Ввод (Inputs)'!$B$17 -> 5188169.6 | ... Z6: =Z5*'Ввод (Inputs)'!$B$17 -> 13904295
A7: Переменные расходы | B7: 0 | C7: =C6*('Ввод (Inputs)'!B18+'Ввод (Inputs)'!B19+'Ввод (Inputs)'!B20) -> 560322.32 | D7: =D6*('Ввод (Inputs)'!B18+'Ввод (Inputs)'!B19+'Ввод (Inputs)'!B20) -> 784451.25 | E7: =E6*('Ввод (Inputs)'!B18+'Ввод (Inputs)'!B19+'Ввод (Inputs)'!B20) -> 1008580.2 | F7: =F6*('Ввод (Inputs)'!B18+'Ввод (Inputs)'!B19+'Ввод (Inputs)'!B20) -> 1232709.1 | G7: =G6*('Ввод (Inputs)'!B18+'Ввод (Inputs)'!B19+'Ввод (Inputs)'!B20) -> 1456838 | H7: =H6*('Ввод (Inputs)'!B18+'Ввод (Inputs)'!B19+'Ввод (Inputs)'!B20) -> 1456838 | I7: =I6*('Ввод (Inputs)'!B18+'Ввод (Inputs)'!B19+'Ввод (Inputs)'!B20) -> 1793031.4 | J7: =J6*('Ввод (Inputs)'!B18+'Ввод (Inputs)'!B19+'Ввод (Inputs)'!B20) -> 2129224.8 | K7: =K6*('Ввод (Inputs)'!B18+'Ввод (Inputs)'!B19+'Ввод (Inputs)'!B20) -> 2465418.2 | L7: =L6*('Ввод (Inputs)'!B18+'Ввод (Inputs)'!B19+'Ввод (Inputs)'!B20) -> 2801611.6 | M7: =M6*('Ввод (Inputs)'!B18+'Ввод (Inputs)'!B19+'Ввод (Inputs)'!B20) -> 3137805 | N7: =N6*('Ввод (Inputs)'!B18+'Ввод (Inputs)'!B19+'Ввод (Inputs)'!B20) -> 3473998.4 | O7: =O6*('Ввод (Inputs)'!B18+'Ввод (Inputs)'!B19+'Ввод (Inputs)'!B20) -> 3810191.8 | P7: =P6*('Ввод (Inputs)'!B18+'Ввод (Inputs)'!B19+'Ввод (Inputs)'!B20) -> 4146385.2 | Q7: =Q6*('Ввод (Inputs)'!B18+'Ввод (Inputs)'!B19+'Ввод (Inputs)'!B20) -> 4482578.6 | R7: =R6*('Ввод (Inputs)'!B18+'Ввод (Inputs)'!B19+'Ввод (Inputs)'!B20) -> 4818772 | S7: =S6*('Ввод (Inputs)'!B18+'Ввод (Inputs)'!B19+'Ввод (Inputs)'!B20) -> 5154965.4 | T7: =T6*('Ввод (Inputs)'!B18+'Ввод (Inputs)'!B19+'Ввод (Inputs)'!B20) -> 5491158.7 | U7: =U6*('Ввод (Inputs)'!B18+'Ввод (Inputs)'!B19+'Ввод (Inputs)'!B20) -> 5827352.1 | V7: =V6*('Ввод (Inputs)'!B18+'Ввод (Inputs)'!B19+'Ввод (Inputs)'!B20) -> 6163545.5 | W7: =W6*('Ввод (Inputs)'!B18+'Ввод (Inputs)'!B19+'Ввод (Inputs)'!B20) -> 6499738.9 | X7: =X6*('Ввод (Inputs)'!B18+'Ввод (Inputs)'!B19+'Ввод (Inputs)'!B20) -> 6835932.3 | Y7: =Y6*('Ввод (Inputs)'!B18+'Ввод (Inputs)'!B19+'Ввод (Inputs)'!B20) -> 7172125.7 | Z7: =Z6*('Ввод (Inputs)'!B18+'Ввод (Inputs)'!B19+'Ввод (Inputs)'!B20) -> 7508319.1
A8: Contribution Margin | B8: 0 | C8: =C6-C7 -> 477311.61 | D8: =D6-D7 -> 668236.25 | E8: =E6-E7 -> 859160.89 | F8: =F6-F7 -> 1050085.5 | G8: =G6-G7 -> 1241010.2 | H8: =H6-H7 -> 1241010.2 | I8: =I6-I7 -> 1527397.1 | J8: =J6-J7 -> 1813784.1 | ... Z8: =Z6-Z7 -> 6395975.5
A9: OPEX (фикс.) | B9: ='Unit Economics'!B14+'Ввод (Inputs)'!B48+'Ввод (Inputs)'!B49 -> 1480235 | C9: ='Unit Economics'!$B$14 -> 1330235 | D9: ='Unit Economics'!$B$14 -> 1330235 | E9: ='Unit Economics'!$B$14 -> 1330235 | F9: ='Unit Economics'!$B$14 -> 1330235 | G9: ='Unit Economics'!$B$14 -> 1330235 | H9: ='Unit Economics'!$B$14 -> 1330235 | I9: ='Unit Economics'!$B$14 -> 1330235 | J9: ='Unit Economics'!$B$14 -> 1330235 | ... Z9: ='Unit Economics'!$B$14 -> 1330235
A10: EBITDA | B10: =-B9 -> -1480235 | C10: =C8-C9 -> -852923.39 | D10: =D8-D9 -> -661998.75 | E10: =E8-E9 -> -471074.11 | F10: =F8-F9 -> -280149.46 | G10: =G8-G9 -> -89224.821 | H10: =H8-H9 -> -89224.821 | I10: =I8-I9 -> 197162.14 | J10: =J8-J9 -> 483549.11 | ... Z10: =Z8-Z9 -> 5065740.5
A11: Амортизация | B11: 0 | C11: =SUM('Ввод (Inputs)'!$B$43:$B$45)/60 -> 18833.333 | D11: =SUM('Ввод (Inputs)'!$B$43:$B$45)/60 -> 18833.333 | E11: =SUM('Ввод (Inputs)'!$B$43:$B$45)/60 -> 18833.333 | F11: =SUM('Ввод (Inputs)'!$B$43:$B$45)/60 -> 18833.333 | G11: =SUM('Ввод (Inputs)'!$B$43:$B$45)/60 -> 18833.333 | H11: =SUM('Ввод (Inputs)'!$B$43:$B$45)/60 -> 18833.333 | I11: =SUM('Ввод (Inputs)'!$B$43:$B$45)/60 -> 18833.333 | J11: =SUM('Ввод (Inputs)'!$B$43:$B$45)/60 -> 18833.333 | ... Z11: =SUM('Ввод (Inputs)'!$B$43:$B$45)/60 -> 18833.333
A12: Налог на прибыль | B12: 0 | C12: =C8*0.25 -> 119327.9 | D12: =D8*0.25 -> 167059.06 | E12: =E8*0.25 -> 214790.22 | F12: =F8*0.25 -> 262521.38 | G12: =G8*0.25 -> 310252.54 | H12: =H8*0.25 -> 310252.54 | I12: =I8*0.25 -> 381849.29 | J12: =J8*0.25 -> 453446.03 | ... Z12: =Z8*0.25 -> 1598993.9
A13: Чистая прибыль | B13: =B10-B11-B12 -> -1480235 | C13: =C10-C11-C12 -> -991084.63 | D13: =D10-D11-D12 -> -847891.15 | E13: =E10-E11-E12 -> -704697.66 | F13: =F10-F11-F12 -> -561504.18 | G13: =G10-G11-G12 -> -418310.7 | H13: =H10-H11-H12 -> -418310.7 | I13: =I10-I11-I12 -> -203520.48 | ... Z13: =Z10-Z11-Z12 -> 3447913.3

Sheet CashFlow
A1: Cash Flow — свободный денежный поток (FCF) и накопленный поток
A3: Статья | B3: М0 | C3: М1 | D3: М2 | E3: М3 | F3: М4 | G3: М5 | H3: М6 | I3: М7 | J3: М8 | K3: М9 | L3: М10 | M3: М11 | N3: М12 | O3: М13 | P3: М14 | Q3: М15 | R3: М16 | S3: М17 | T3: М18 | U3: М19 | V3: М20 | W3: М21 | X3: М22 | Y3: М23 | Z3: М24
A4: Чистая прибыль | B4: ='P&L_24м'!B13 -> -1480235 | C4: ='P&L_24м'!C13 -> -991084.63 | D4: ='P&L_24м'!D13 -> -847891.15 | E4: ='P&L_24м'!E13 -> -704697.66 | F4: ='P&L_24м'!F13 -> -561504.18 | G4: ='P&L_24м'!G13 -> -418310.7 | H4: ='P&L_24м'!H13 -> -418310.7 | I4: ='P&L_24м'!I13 -> -203520.48 | ... Z4: ='P&L_24м'!Z13 -> 3447913.3
A5: + Амортизация | B5: ='P&L_24м'!B11 -> 0 | C5: ='P&L_24м'!C11 -> 18833.333 | D5: ='P&L_24м'!D11 -> 18833.333 | E5: ='P&L_24м'!E11 -> 18833.333 | F5: ='P&L_24м'!F11 -> 18833.333 | G5: ='P&L_24м'!G11 -> 18833.333 | H5: ='P&L_24м'!H11 -> 18833.333 | I5: ='P&L_24м'!I11 -> 18833.333 | ... Z5: ='P&L_24м'!Z11 -> 18833.333
A6: Операционный денежный поток | B6: =B4+B5 -> -1480235 | C6: =C4+C5 -> -972251.29 | D6: =D4+D5 -> -829057.81 | E6: =E4+E5 -> -685864.33 | F6: =F4+F5 -> -542670.85 | G6: =G4+G5 -> -399477.37 | H6: =H4+H5 -> -399477.37 | I6: =I4+I5 -> -184687.14 | ... Z6: =Z4+Z5 -> 3466746.7
A7: Инвестиции (CAPEX + оборотный капитал) | B7: =SUM('Ввод (Inputs)'!B43:B46) -> 1192235
A8: Свободный денежный поток (FCF) | B8: =B6+B7 -> -288000 | C8: =C6+C7 -> -972251.29 | D8: =D6+D7 -> -829057.81 | E8: =E6+E7 -> -685864.33 | F8: =F6+F7 -> -542670.85 | G8: =G6+G7 -> -399477.37 | H8: =H6+H7 -> -399477.37 | I8: =I6+I7 -> -184687.14 | ... Z8: =Z6+Z7 -> 3466746.7
A9: Накопленный FCF | B9: =B8 -> -288000 | C9: =B9+C8 -> -1260251.3 | D9: =C9+D8 -> -2089309.1 | E9: =D9+E8 -> -2775173.4 | F9: =E9+F8 -> -3317844.3 | G9: =F9+G8 -> -3717321.7 | H9: =G9+H8 -> -4116799 | I9: =H9+I8 -> -4301486.2 | J9: =I9+J8 -> -4271383.1 | ... Z9: =Y9+Z8 -> 25421737

Sheet Метрики
A1: Инвестиционные метрики
A2: Метрика | B2: Значение
A4: NPV | B4: {=NPV((1+'Ввод (Inputs)'!B40)^(1/12)-1,CashFlow!C8:Z8)+CashFlow!B8} -> 18210820
A5: IRR (месячная) | B5: =IRR(CashFlow!B8:Z8) -> 0.13551353
A6: IRR (годовая) | B6: =(1+B5)^12-1 -> 3.5952352
A7: Payback Period (мес) | B7: {=INDEX(CashFlow!B3:Z3,MATCH(TRUE,CashFlow!B9:Z9>=0,0))} -> М14
A8: LTV/CAC (первые 5 месяцев) | B8: ='Unit Economics'!B37 -> 4.7731161
A9: LTV/CAC (после 5 месяцев) | B9: ='Unit Economics'!B42 -> 11.93279

Sheet Анализ чувствительности
A1: Анализ чувствительности (Sensitivity Analysis)
A3: ОДНОФАКТОРНЫЙ АНАЛИЗ
A4: Цена | B4: NPV | C4: IRR (месячная) | D4: IRR (годовая) | E4: PP | F4: LTV/CAC (первые 5 месяцев) | G4: LTV/CAC (после 5 месяцев) | H4: Вердикт
A5: 42260 | B5: =Метрики!B4 -> 18210820 | C5: =Метрики!B5 -> 0.13551353 | D5: =Метрики!B6 -> 3.5952352 | E5: =Метрики!B7 -> М14 | F5: =Метрики!B8 -> 4.7731161 | G5: =Метрики!B9 -> 11.93279 | H5: =IF(AND(B5>0, D5>0.2, VALUE(RIGHT(E5, LEN(E5)-1))<24), "GO", "NO-GO") -> GO
A7: Цена | B7: NPV | C7: IRR (месячная) | D7: IRR (годовая) | E7: PP | F7: LTV/CAC (первые 5 месяцев) | G7: LTV/CAC (после 5 месяцев) | H7: Вердикт
A8: 35000 | B8: 10471783 | C8: 0.0905 | D8: 1.8294 | E8: М17 | F8: 3.95 | G8: 9.88 | H8: GO
A9: 42260 | B9: 18210820 | C9: 0.1355 | D9: 3.5952 | E9: М14 | F9: 4.77 | G9: 11.93 | H9: GO
A10: 50000 | B10: 26461529 | C10: 0.1802 | D10: 6.3057 | E10: М12 | F10: 5.65 | G10: 14.12 | H10: GO
A16: СЦЕНАРНЫЙ АНАЛИЗ
A17: Параметр | B17: ПЕССИМИСТИЧНЫЙ | C17: БАЗОВЫЙ | D17: ОПТИМИСТИЧНЫЙ | E17: ТУМБЛЕРЫ
A18: Цена | B18: 35000 | C18: 42260 | D18: 50000 | E18: =A5 -> 42260
A19: Маркетинг | B19: 150000 | C19: 200000 | D19: 250000 | E19: 200000
A20: Food cost как % от выручки | B20: 0.36 | C20: 0.33 | D20: 0.3 | E20: 0.33
A21: Прирост загрузки в первые 5 месяцев % | B21: 0.01 | C21: 0.02 | D21: 0.03 | E21: 0.02
A22: Прирост загрузки после 5 месяцев % | B22: 0.03 | C22: 0.05 | D22: 0.07 | E22: 0.05
A23: NPV (чистая приведённая стоимость) | B23: 15052641 | C23: 18210820 | D23: 20366559
A24: IRR (месячная) | B24: 0.1051 | C24: 0.1355 | D24: 0.1795
A25: IRR (годовая) | B25: 2.3159 | C25: 3.5952 | D25: 6.2515
A26: PP Срок окупаемости (месяцев) | B26: М16 | C26: M14 | D26: М11
A27: LTV/CAC (первые 5 месяцев) | B27: 2.64 | C27: 4.77 | D27: 6.78
A28: LTV/CAC (после 5 месяцев) | B28: 13.18 | C28: 11.93 | D28: 11.29
A29: Вердикт | B29: =IF(AND(B23>0, B25>0.2, 16<24, B27>3, B28>3), "GO", "NO-GO") -> NO-GO | C29: =IF(AND(C23>0, C25>0.2, 14<24, C27>3, C28>3), "GO", "NO-GO") -> GO | D29: =IF(AND(D23>0, D25>0.2, 11<24, D27>3, D28>3), "GO", "NO-GO") -> GO
A31: Анализ чувствительности (Sensitivity Analysis)
